Workbook

Sheet About
A1: AR Open Items - Power Query cleaning example
A3: A messy accounts-receivable open-items print (670 lines, 497 real open items) cleaned with Power Query.
A4: All customers, invoice numbers and amounts are fictitious.
A6: Sheets
A7: Raw_Data The export exactly as it came out: titles, page footers, subtotals, repeated headers, duplicates, mixed formats.
A8: Cleaned_Data The output of the AR_Open_Items_Clean query (one row per open document, typed columns, ageing added).
A9: Before_After 30 real fields from the raw file next to what the query turns them into, and which step does it.
A10: Issues_Log Every problem found in the raw file, how it is handled, and how many lines it touched.
A11: Aging_Summary Ageing by bucket and currency, and by customer. Live formulas on Cleaned_Data. Reconciled to the report footer.
A12: Cust_Master / Rep_Alias The two lookup tables the query joins to.
A13: M_Code The main query, for pasting into Data > Get Data > Blank Query > Advanced Editor.
A15: Running it yourself
... A21: Credit notes and on-account receipts are always negative. Blank currency is taken as INR. Blank terms use the customer master default.

Sheet Raw_Data
A1: Hosur Road Industrial Supplies Pvt Ltd
A2: Accounts Receivable - Open Items by Customer
A3: As on 30/09/2026 | J3: Run date: 01/10/2026 08:42
A4: Selection: all customers, all posting keys | Currency: document currency
A6: Cust Code | B6: Customer Name | C6: Doc No | D6: Type | E6: Doc Date | F6: Due Date | G6: Amount | H6: Curr | I6: Terms | J6: Sales Rep | K6: PO / Ref | L6: Remarks
A7: C10008 | B7: Sagar Polypack | C7: HR/25-26/01088 | D7: INV | E7: 09/12/2025 | F7: 08/01/2026 | G7: 96,594.74 | H7: INR | I7: Net 30 | J7: Anitha Rao | K7: PO/26/738
C8: JV/25-26/0031 | D8: JV | E8: 27-Feb-26 | G8: -18,185.08 | H8: INR | J8: A. Rao
C9: HR/25-26/03028 | D9: INV | E9: 03/03/2026 | F9: 02/04/2026 | G9: 44,604.00 | H9: inr | J9: Anitha R. | K9: none | L9: PTP 15/10
C10: HR/25-26/04023 | D10: INV | E10: 29/03/2026 | G10: 39,270.00 | H10: ₹ | I10: Net 30 | J10: Anitha Rao | K10: PO/26/116
C11: HR/26-27/00424 | D11: INV | E11: 05/06/2026 | F11: 05/07/2026 | G11: 104,685.00 | H11: INR | I11: 30 days | J11: anitha rao | K11: PO-5305
C12: HR/26-27/00716 | D12: INV | E12: 11-Jul-26 | F12: 10-Aug-26 | G12: Rs. 224,663.47 | H12: INR | I12: 30 Days | J12: Anitha R. | K12: PO/26/505
C13: HR/26-27/00691 | D13: INV | E13: 08/07/2026 | F13: 07/08/2026 | G13: 17346.00 | H13: INR | I13: Net 30
C14: DN/26-27/0016 | D14: DN | E14: 02/08/2026 | F14: 01/09/2026 | G14: 1,988.36 | H14: inr | I14: Net 30 | J14: Anitha R. | K14: PO-5807
C15: HR/26-27/01104 | D15: INV | E15: 02-Aug-26 | F15: 01-Sep-26 | G15: 80,478.64 | I15: Net 30 | J15: ANITHA R | K15: WO-624
C16: HR/26-27/01160 | D16: INV | E16: 06/08/2026 | F16: 05/09/2026 | G16: 138,916.85 | H16: INR | I16: NET30 | J16: ANITHA R | K16: PO-6241
C17: HR/26-27/01487 | D17: INV | E17: 46260 | F17: 46275 | G17: 50,268.00 | H17: INR | I17: Net 15 | J17: Anitha Rao | K17: 4597152166
C18: HR/26-27/01874 | D18: INV | E18: 09/09/2026 | F18: 09/10/2026 | G18: Rs. 84,684.97 | H18: INR | I18: 30 days | J18: anitha rao
C19: HR/26-27/02095 | D19: INV | E19: 17/09/2026 | F19: 17/10/2026 | G19: 368450.74 | H19: INR | I19: 30 days | J19: A. Rao | K19: PO/25/481
C20: HR/26-27/02244 | D20: INV | E20: 21/09/2026 | F20: 21/10/2026 | G20: 192,340.00 | H20: INR | I20: Net 30 | J20: Anitha R. | K20: PO-8122
C21: HR/26-27/02376 | D21: INV | E21: 26 Sep 2026 | F21: 26/10/2026 | G21: 147,618.00 | H21: INR | I21: Net30 | J21: Anitha Rao | K21: PO/26/467
C22: ** Customer total ** | G22: 15,73,723.69 | H22: INR
A23: C10011 | B23: Sri Lakshmi Traders | C23: CN/26-27/0071 | D23: CR NOTE | E23: 08/08/2026 | G23: 20,619.99- | H23: INR | J23: Divya N.
C24: HR/26-27/01548 | D24: INV | E24: 27/08/2026 | F24: 26/09/2026 | G24: 140,774.00 | H24: INR | I24: Net30 | J24: Divya Nair | K24: -
C25: ** Customer total ** | G25: 1,20,154.01 | H25: INR
A27: C10017 | B27: Jayanagar Hardware Mart | C27: HR/26-27/00720 | D27: INV | E27: 14/07/2026 | F27: 29/07/2026 | G27: Rs. 61,360.00 | H27: INR | I27: Net15 | J27: A. Rao | K27: NA
C28: HR/26-27/01368 | D28: INV | E28: 2026-08-21 | F28: 05/09/2026 | G28: 28,084.00 | H28: INR | I28: Net15 | J28: Anitha Rao
C29: HR/26-27/01665 | D29: INV | E29: 02/09/2026 | F29: 17/09/2026 | G29: 15,340 | H29: INR | I29: Net 15 | J29: anitha rao
C30: ** Customer total ** | G30: 1,04,784.00 | H30: INR
A32: C10021 | B32: Konkan Marine Equipments | C32: HR/25-26/00693 | D32: INV | E32: 13/11/2025 | F32: 28/12/2025 | G32: 57,015.00 | H32: INR | I32: Net 45 | J32: Suresh Babu | K32: PO-2314 | L32: part payment recd, bal pending
C33: HR/25-26/02229 | D33: INV | E33: 17/01/2026 | F33: 03/03/2026 | G33: 560,146.00 | H33: inr | I33: 45 Days | J33: anitha rao | K33: PO/25/476
C34: HR/25-26/03868 | D34: inv | E34: 26/03/2026 | F34: 10/05/2026 | G34: Rs. 27,258.00 | H34: INR | I34: NET45 | J34: anitha rao | K34: PO/25/676
C35: HR/25-26/04223 | D35: INV | E35: 31/03/2026 | F35: 15/05/2026 | G35: 25,760.00 | H35: INR | I35: NET45 | J35: Anitha Rao
C36: DN/26-27/0002 | D36: Dr Note | E36: 05/06/2026 | F36: 20/07/2026 | G36: 4,480.00 | H36: INR | I36: Net 45 | J36: Anitha Rao | K36: WO-495
C37: HR/26-27/00489 | D37: INV | E37: 18/06/2026 | F37: 02-Aug-26 | G37: 402,380.00 | H37: INR | I37: 45 Days | J37: Anitha Rao
C38: HR/26-27/00413 | D38: INV | E38: 03-Jun-26 | F38: 18-Jul-26 | G38: 606,900.00 | H38: INR | I38: 45 Days | J38: Ramesh | K38: PO-1164
C39: HR/26-27/00876 | D39: INV | E39: 21-Jul-26 | F39: 04-Sep-26 | G39: 46,451.21 | H39: INR | I39: Net 45 | J39: A. Rao | K39: PO-6449
C40: HR/26-27/00973 | D40: INV | E40: 26/07/2026 | F40: 09/09/2026 | G40: 11,303.68 | H40: INR | I40: NET45 | K40: 4512095782
C41: HR/26-27/01162 | D41: INV | E41: 07.08.2026 | F41: 21.09.2026 | G41: 56,286.00 | H41: INR | I41: Net 45 | J41: Anitha Rao | K41: PO-4393
C42: HR/26-27/01344 | D42: INV | E42: 19/08/2026 | F42: 03/10/2026 | G42: 66,394.53 | H42: INR | I42: N45 | J42: anitha rao | K42: WO-551
C43: HR/ 26-27/01363 | D43: INV | E43: 21-Aug-26 | F43: 20-Oct-26 | G43: 35,754.00 | H43: INR | I43: Net 60 | J43: Anitha Rao | K43: PO-9573
...

Sheet Cleaned_Data
A1: CustCode | B1: CustomerName | C1: Region | D1: Segment | E1: DocNo | F1: DocType | G1: DocDate | H1: DueDate | I1: TermsDays | J1: Currency | K1: Amount | L1: SalesRep | M1: PORef | N1: Remarks | O1: IsDisputed | P1: DaysPastDue | Q1: AgingBucket | R1: DataFlag
A2: C10008 | B2: Sagar Polypack | C2: Andhra Pradesh | D2: Packaging | E2: HR/25-26/01088 | F2: Invoice | G2: 46000 | H2: 46030 | I2: 30 | J2: INR | K2: 96594.74 | L2: Anitha Rao | M2: PO/26/738 | O2: =FALSE() -> FALSE | P2: 265 | Q2: 180+
A3: C10008 | B3: Sagar Polypack | C3: Andhra Pradesh | D3: Packaging | E3: JV/25-26/0031 | F3: Journal | G3: 46080 | H3: 46080 | I3: 0 | J3: INR | K3: -18185.08 | L3: Anitha Rao | O3: =FALSE() -> FALSE | P3: 215 | Q3: 180+
A4: C10008 | B4: Sagar Polypack | C4: Andhra Pradesh | D4: Packaging | E4: HR/25-26/03028 | F4: Invoice | G4: 46084 | H4: 46114 | I4: 30 | J4: INR | K4: 44604 | L4: Anitha Rao | N4: PTP 15/10 | O4: =FALSE() -> FALSE | P4: 181 | Q4: 180+ | R4: terms blank - master default
A5: C10008 | B5: Sagar Polypack | C5: Andhra Pradesh | D5: Packaging | E5: HR/25-26/04023 | F5: Invoice | G5: 46110 | H5: 46140 | I5: 30 | J5: INR | K5: 39270 | L5: Anitha Rao | M5: PO/26/116 | O5: =FALSE() -> FALSE | P5: 155 | Q5: 91-180 | R5: due date missing - derived from terms
A6: C10008 | B6: Sagar Polypack | C6: Andhra Pradesh | D6: Packaging | E6: HR/26-27/00424 | F6: Invoice | G6: 46178 | H6: 46208 | I6: 30 | J6: INR | K6: 104685 | L6: Anitha Rao | M6: PO-5305 | O6: =FALSE() -> FALSE | P6: 87 | Q6: 61-90
A7: C10008 | B7: Sagar Polypack | C7: Andhra Pradesh | D7: Packaging | E7: HR/26-27/00691 | F7: Invoice | G7: 46211 | H7: 46241 | I7: 30 | J7: INR | K7: 17346 | L7: Unassigned | O7: =FALSE() -> FALSE | P7: 54 | Q7: 31-60
A8: C10008 | B8: Sagar Polypack | C8: Andhra Pradesh | D8: Packaging | E8: HR/26-27/00716 | F8: Invoice | G8: 46214 | H8: 46244 | I8: 30 | J8: INR | K8: 224663.47 | L8: Anitha Rao | M8: PO/26/505 | O8: =FALSE() -> FALSE | P8: 51 | Q8: 31-60
A9: C10008 | B9: Sagar Polypack | C9: Andhra Pradesh | D9: Packaging | E9: DN/26-27/0016 | F9: Debit Note | G9: 46236 | H9: 46266 | I9: 30 | J9: INR | K9: 1988.36 | L9: Anitha Rao | M9: PO-5807 | O9: =FALSE() -> FALSE | P9: 29 | Q9: 1-30
A10: C10008 | B10: Sagar Polypack | C10: Andhra Pradesh | D10: Packaging | E10: HR/26-27/01104 | F10: Invoice | G10: 46236 | H10: 46266 | I10: 30 | J10: INR | K10: 80478.64 | L10: Anitha Rao | M10: WO-624 | O10: =FALSE() -> FALSE | P10: 29 | Q10: 1-30 | R10: currency blank - assumed INR
A11: C10008 | B11: Sagar Polypack | C11: Andhra Pradesh | D11: Packaging | E11: HR/26-27/01160 | F11: Invoice | G11: 46240 | H11: 46270 | I11: 30 | J11: INR | K11: 138916.85 | L11: Anitha Rao | M11: PO-6241 | O11: =FALSE() -> FALSE | P11: 25 | Q11: 1-30
A12: C10008 | B12: Sagar Polypack | C12: Andhra Pradesh | D12: Packaging | E12: HR/26-27/01487 | F12: Invoice | G12: 46260 | H12: 46275 | I12: 15 | J12: INR | K12: 50268 | L12: Anitha Rao | M12: 4597152166 | O12: =FALSE() -> FALSE | P12: 20 | Q12: 1-30
A13: C10008 | B13: Sagar Polypack | C13: Andhra Pradesh | D13: Packaging | E13: HR/26-27/01874 | F13: Invoice | G13: 46274 | H13: 46304 | I13: 30 | J13: INR | K13: 84684.97 | L13: Anitha Rao | O13: =FALSE() -> FALSE | P13: -9 | Q13: Not due
A14: C10008 | B14: Sagar Polypack | C14: Andhra Pradesh | D14: Packaging | E14: HR/26-27/02095 | F14: Invoice | G14: 46282 | H14: 46312 | I14: 30 | J14: INR | K14: 368450.74 | L14: Anitha Rao | M14: PO/25/481 | O14: =FALSE() -> FALSE | P14: -17 | Q14: Not due
A15: C10008 | B15: Sagar Polypack | C15: Andhra Pradesh | D15: Packaging | E15: HR/26-27/02244 | F15: Invoice | G15: 46286 | H15: 46316 | I15: 30 | J15: INR | K15: 192340 | L15: Anitha Rao | M15: PO-8122 | O15: =FALSE() -> FALSE | P15: -21 | Q15: Not due
A16: C10008 | B16: Sagar Polypack | C16: Andhra Pradesh | D16: Packaging | E16: HR/26-27/02376 | F16: Invoice | G16: 46291 | H16: 46321 | I16: 30 | J16: INR | K16: 147618 | L16: Anitha Rao | M16: PO/26/467 | O16: =FALSE() -> FALSE | P16: -26 | Q16: Not due
A17: C10011 | B17: Sri Lakshmi Traders | C17: Tamil Nadu | D17: Trading | E17: CN/26-27/0071 | F17: Credit Note | G17: 46242 | H17: 46242 | I17: 0 | J17: INR | K17: -20619.99 | L17: Divya Nair | O17: =FALSE() -> FALSE | P17: 53 | Q17: 31-60
A18: C10011 | B18: Sri Lakshmi Traders | C18: Tamil Nadu | D18: Trading | E18: HR/26-27/01548 | F18: Invoice | G18: 46261 | H18: 46291 | I18: 30 | J18: INR | K18: 140774 | L18: Divya Nair | O18: =FALSE() -> FALSE | P18: 4 | Q18: 1-30
A19: C10017 | B19: Jayanagar Hardware Mart | C19: Bengaluru | D19: Trading | E19: HR/26-27/00720 | F19: Invoice | G19: 46217 | H19: 46232 | I19: 15 | J19: INR | K19: 61360 | L19: Anitha Rao | O19: =FALSE() -> FALSE | P19: 63 | Q19: 61-90
A20: C10017 | B20: Jayanagar Hardware Mart | C20: Bengaluru | D20: Trading | E20: HR/26-27/01368 | F20: Invoice | G20: 46255 | H20: 46270 | I20: 15 | J20: INR | K20: 28084 | L20: Anitha Rao | O20: =FALSE() -> FALSE | P20: 25 | Q20: 1-30
A21: C10017 | B21: Jayanagar Hardware Mart | C21: Bengaluru | D21: Trading | E21: HR/26-27/01665 | F21: Invoice | G21: 46267 | H21: 46282 | I21: 15 | J21: INR | K21: 15340 | L21: Anitha Rao | O21: =FALSE() -> FALSE | P21: 13 | Q21: 1-30
A22: C10021 | B22: Konkan Marine Equipments | C22: Maharashtra | D22: Engineering | E22: HR/25-26/00693 | F22: Invoice | G22: 45974 | H22: 46019 | I22: 45 | J22: INR | K22: 57015 | L22: Suresh Babu | M22: PO-2314 | N22: part payment recd, bal pending | O22: =FALSE() -> FALSE | P22: 276 | Q22: 180+
A23: C10021 | B23: Konkan Marine Equipments | C23: Maharashtra | D23: Engineering | E23: HR/25-26/02229 | F23: Invoice | G23: 46039 | H23: 46084 | I23: 45 | J23: INR | K23: 560146 | L23: Anitha Rao | M23: PO/25/476 | O23: =FALSE() -> FALSE | P23: 211 | Q23: 180+
A24: C10021 | B24: Konkan Marine Equipments | C24: Maharashtra | D24: Engineering | E24: HR/25-26/03868 | F24: Invoice | G24: 46107 | H24: 46152 | I24: 45 | J24: INR | K24: 27258 | L24: Anitha Rao | M24: PO/25/676 | O24: =FALSE() -> FALSE | P24: 143 | Q24: 91-180
A25: C10021 | B25: Konkan Marine Equipments | C25: Maharashtra | D25: Engineering | E25: HR/25-26/04223 | F25: Invoice | G25: 46112 | H25: 46157 | I25: 45 | J25: INR | K25: 25760 | L25: Anitha Rao | O25: =FALSE() -> FALSE | P25: 138 | Q25: 91-180
A26: C10021 | B26: Konkan Marine Equipments | C26: Maharashtra | D26: Engineering | E26: HR/26-27/00413 | F26: Invoice | G26: 46176 | H26: 46221 | I26: 45 | J26: INR | K26: 606900 | L26: Ramesh Kumar | M26: PO-1164 | O26: =FALSE() -> FALSE | P26: 74 | Q26: 61-90
A27: C10021 | B27: Konkan Marine Equipments | C27: Maharashtra | D27: Engineering | E27: DN/26-27/0002 | F27: Debit Note | G27: 46178 | H27: 46223 | I27: 45 | J27: INR | K27: 4480 | L27: Anitha Rao | M27: WO-495 | O27: =FALSE() -> FALSE | P27: 72 | Q27: 61-90
A28: C10021 | B28: Konkan Marine Equipments | C28: Maharashtra | D28: Engineering | E28: HR/26-27/00489 | F28: Invoice | G28: 46191 | H28: 46236 | I28: 45 | J28: INR | K28: 402380 | L28: Anitha Rao | O28: =FALSE() -> FALSE | P28: 59 | Q28: 31-60
A29: C10021 | B29: Konkan Marine Equipments | C29: Maharashtra | D29: Engineering | E29: HR/26-27/00876 | F29: Invoice | G29: 46224 | H29: 46269 | I29: 45 | J29: INR | K29: 46451.21 | L29: Anitha Rao | M29: PO-6449 | O29: =FALSE() -> FALSE | P29: 26 | Q29: 1-30
A30: C10021 | B30: Konkan Marine Equipments | C30: Maharashtra | D30: Engineering | E30: HR/26-27/00973 | F30: Invoice | G30: 46229 | H30: 46274 | I30: 45 | J30: INR | K30: 11303.68 | L30: Unassigned | M30: 4512095782 | O30: =FALSE() -> FALSE | P30: 21 | Q30: 1-30
A31: C10021 | B31: Konkan Marine Equipments | C31: Maharashtra | D31: Engineering | E31: HR/26-27/01162 | F31: Invoice | G31: 46241 | H31: 46286 | I31: 45 | J31: INR | K31: 56286 | L31: Anitha Rao | M31: PO-4393 | O31: =FALSE() -> FALSE | P31: 9 | Q31: 1-30
A32: C10021 | B32: Konkan Marine Equipments | C32: Maharashtra | D32: Engineering | E32: HR/26-27/01344 | F32: Invoice | G32: 46253 | H32: 46298 | I32: 45 | J32: INR | K32: 66394.53 | L32: Anitha Rao | M32: WO-551 | O32: =FALSE() -> FALSE | P32: -3 | Q32: Not due
A33: C10021 | B33: Konkan Marine Equipments | C33: Maharashtra | D33: Engineering | E33: HR/26-27/01363 | F33: Invoice | G33: 46255 | H33: 46315 | I33: 60 | J33: INR | K33: 35754 | L33: Anitha Rao | M33: PO-9573 | O33: =FALSE() -> FALSE | P33: -20 | Q33: Not due
A34: C10021 | B34: Konkan Marine Equipments | C34: Maharashtra | D34: Engineering | E34: CN/26-27/0087 | F34: Credit Note | G34: 46256 | H34: 46256 | I34: 0 | J34: INR | K34: -55658.43 | L34: Unassigned | M34: ret. goods | O34: =FALSE() -> FALSE | P34: 39 | Q34: 31-60
A35: C10021 | B35: Konkan Marine Equipments | C35: Maharashtra | D35: Engineering | E35: HR/26-27/01968 | F35: Invoice | G35: 46279 | H35: 46324 | I35: 45 | J35: INR | K35: 45062.24 | L35: Anitha Rao | M35: PO/25/366 | O35: =FALSE() -> FALSE | P35: -29 | Q35: Not due
A36: C10021 | B36: Konkan Marine Equipments | C36: Maharashtra | D36: Engineering | E36: HR/26-27/01988 | F36: Invoice | G36: 46280 | H36: 46325 | I36: 45 | J36: INR | K36: 73925.76 | L36: Anitha Rao | M36: WO-367 | O36: =FALSE() -> FALSE | P36: -30 | Q36: Not due
A37: C10021 | B37: Konkan Marine Equipments | C37: Maharashtra | D37: Engineering | E37: HR/26-27/02020 | F37: Invoice | G37: 46280 | H37: 46325 | I37: 45 | J37: INR | K37: 81920 | L37: Anitha Rao | M37: PO/26/267 | O37: =FALSE() -> FALSE | P37: -30 | Q37: Not due | R37: due date missing - derived from terms
A38: C10021 | B38: Konkan Marine Equipments | C38: Maharashtra | D38: Engineering | E38: HR/26-27/02104 | F38: Invoice | G38: 46283 | H38: 46328 | I38: 45 | J38: INR | K38: 476838 | L38: Anitha Rao | M38: PO-9754 | O38: =FALSE() -> FALSE | P38: -33 | Q38: Not due
A39: C10021 | B39: Konkan Marine Equipments | C39: Maharashtra | D39: Engineering | E39: HR/26-27/02194 | F39: Invoice | G39: 46285 | H39: 46330 | I39: 45 | J39: INR | K39: 37760 | L39: Anitha Rao | M39: PO-8511 | O39: =FALSE() -> FALSE | P39: -35 | Q39: Not due
A40: C10029 | B40: Peenya Precision Tools | C40: Bengaluru | D40: Engineering | E40: HR/26-27/00299 | F40: Invoice | G40: 46163 | H40: 46208 | I40: 45 | J40: INR | K40: 46964 | L40: Suresh Babu | M40: PO-9393 | N40: PTP 15/10 | O40: =FALSE() -> FALSE | P40: 87 | Q40: 61-90
...

Sheet Before_After
A1: Before and after - real fields from the raw file
A2: Raw values are shown in quotes so stray spaces are visible. Doc No is the clean document number the row ends up under.
A4: Field | B4: What is wrong | C4: Before (raw) | D4: After (clean) | E4: Query step | F4: Doc No
A5: Customer code | B5: lower case | C5: "c10031" | D5: C10031 | E5: CodeFix | F5: HR/25-26/02270
A6: Customer code | B6: extra dash | C6: "C-10156" | D6: C10156 | E6: CodeFix | F6: HR/25-26/02973
A7: Customer code + name | B7: only printed on first line of the block | C7: (blank) / (blank) | D7: C10008 / Sagar Polypack | E7: FillDown | F7: JV/25-26/0031
A8: Customer name | B8: shouted in capitals | C8: "MAHALAKSHMI FASTENERS" | D8: "Mahalakshmi Fasteners" | E8: JoinCust (master) | F8: HR/25-26/02067
A9: Customer name | B9: company suffix written differently | C9: "Deccan Pumps & Motors Private Limited" | D9: "Deccan Pumps & Motors Pvt Ltd" | E9: JoinCust (master) | F9: HR/25-26/00340
A10: Customer name | B10: new customer, not in master yet | C10: "kumaran alloys" | D10: "Kumaran Alloys" + flag | E10: CustomerName (Text.Proper) + DataFlag | F10: HR/25-26/00203
A11: Doc type | B11: long-hand code | C11: "Cr Note" | D11: Credit Note | E11: DocTypeMap | F11: CN/26-27/0087
A12: Doc type | B12: three codes for the same thing | C12: "ADV" | D12: On-Account Receipt | E12: DocTypeMap | F12: RCT/26-27/00625
A13: Doc no | B13: stray spaces / lower case | C13: " HR/26-27/01968" | D13: "HR/26-27/01968" | E13: DocNoStd | F13: HR/26-27/01968
A14: Doc date | B14: Excel serial number saved as text | C14: "46260" | D14: 2026-08-26 | E14: fnParseDate | F14: HR/26-27/01487
A15: Doc date | B15: dd-Mon-yy | C15: "11-Jul-26" | D15: 2026-07-11 | E15: fnParseDate | F15: HR/26-27/00716
... A34: Remarks | B34: free text dispute note | C34: "DISP" | D34: IsDisputed = TRUE | E34: IsDisputed | F34: HR/25-26/02618

Sheet Issues_Log
A1: Issues found in the raw export
A2: Raw file: 670 lines -> 510 document lines -> 497 clean open items. Counts are lines (or cells, for dates) in the raw file, taken from the CSV.
A4: # | B4: What is wrong in the raw export | C4: How the query handles it | D4: Step | E4: Count
A5: 1 | B5: Report furniture: titles, page footers, blank lines, repeated column headers, customer totals and grand totals | C5: Keep only rows that have a document Type, and drop the repeated header row | D5: DocLines | E5: 160
A6: 2 | B6: Customer code and name printed only on the first line of each customer block | C6: Table.FillDown on both columns | D6: Filled | E6: 439
A7: 3 | B7: Customer code typed several ways (c10031, C-10156, "C 10156", trailing space) | C7: Upper-case, remove dashes and spaces | D7: CodeFix | E7: 17
A8: 4 | B8: Customer name spelled differently from the master (capitals, Pvt. Ltd. / Private Limited, & / and) | C8: Take the name from the customer master, joined on the code | D8: JoinCust | E8: 12
A9: 5 | B9: Customer not in the master | C9: Fall back to the raw name in proper case, and flag the row | D9: CustomerName / DataFlag | E9: 17
A10: 6 | B10: Document type written as INV / Inv / INVOICE, CN / Cr Note, RCT / PMT / ADV and so on | C10: Map to five standard types | D10: DocTypeStd | E10: 86
A11: 7 | B11: Document numbers with stray spaces or lower case | C11: Remove spaces, upper-case | D11: DocNoStd | E11: 60
A12: 8 | B12: Dates in six formats, including Excel serial numbers saved as text (cells, doc date + due date) | C12: fnParseDate tries each format explicitly | D12: DocDateP / DueDateP | E12: 260
A13: 9 | B13: Amounts stored as text: brackets, trailing minus, Rs. / rupee sign, lakh grouping (1,24,500.00) | C13: fnParseAmount strips symbols and commas and applies the sign | D13: AmountP | E13: 123
A14: 10 | B14: Credit notes / receipts printed as positive numbers | C14: Force negative for Credit Note and On-Account Receipt | D14: AmountSigned | E14: 12
A15: 11 | B15: Currency written as INR, Rs, the rupee sign, inr, US$, the euro sign... | C15: Map to ISO codes | D15: Currency | E15: 87
A16: 12 | B16: Currency blank | C16: Assume INR (functional currency) and flag | D16: Currency / DataFlag | E16: 22
... A24: 20 | B24: Lines repeated at the top of the next page, and a few double postings | C24: Distinct on customer + doc no + type + amount (after standardising) | D24: Deduped | E24: 13

Sheet Aging_Summary
A1: Receivables ageing
A3: As on date | B3: 46295 | C3: Input: report date from the raw file header. Ageing buckets in Cleaned_Data were built against this date.
A5: Bucket | B5: INR | C5: USD | D5: EUR | E5: Items
A6: Not due | B6: =SUMIFS(Cleaned_Data!$K$2:$K$498,Cleaned_Data!$Q$2:$Q$498,$A6,Cleaned_Data!$J$2:$J$498,B$5) -> 17475656 | C6: =SUMIFS(Cleaned_Data!$K$2:$K$498,Cleaned_Data!$Q$2:$Q$498,$A6,Cleaned_Data!$J$2:$J$498,C$5) -> 38448.34 | D6: =SUMIFS(Cleaned_Data!$K$2:$K$498,Cleaned_Data!$Q$2:$Q$498,$A6,Cleaned_Data!$J$2:$J$498,D$5) -> 6031 | E6: =COUNTIFS(Cleaned_Data!$Q$2:$Q$498,$A6) -> 153
A7: 1-30 | B7: =SUMIFS(Cleaned_Data!$K$2:$K$498,Cleaned_Data!$Q$2:$Q$498,$A7,Cleaned_Data!$J$2:$J$498,B$5) -> 6971835.1 | C7: =SUMIFS(Cleaned_Data!$K$2:$K$498,Cleaned_Data!$Q$2:$Q$498,$A7,Cleaned_Data!$J$2:$J$498,C$5) -> 25706.53 | D7: =SUMIFS(Cleaned_Data!$K$2:$K$498,Cleaned_Data!$Q$2:$Q$498,$A7,Cleaned_Data!$J$2:$J$498,D$5) -> 0 | E7: =COUNTIFS(Cleaned_Data!$Q$2:$Q$498,$A7) -> 97
A8: 31-60 | B8: =SUMIFS(Cleaned_Data!$K$2:$K$498,Cleaned_Data!$Q$2:$Q$498,$A8,Cleaned_Data!$J$2:$J$498,B$5) -> 4532542.1 | C8: =SUMIFS(Cleaned_Data!$K$2:$K$498,Cleaned_Data!$Q$2:$Q$498,$A8,Cleaned_Data!$J$2:$J$498,C$5) -> 0 | D8: =SUMIFS(Cleaned_Data!$K$2:$K$498,Cleaned_Data!$Q$2:$Q$498,$A8,Cleaned_Data!$J$2:$J$498,D$5) -> 0 | E8: =COUNTIFS(Cleaned_Data!$Q$2:$Q$498,$A8) -> 60
A9: 61-90 | B9: =SUMIFS(Cleaned_Data!$K$2:$K$498,Cleaned_Data!$Q$2:$Q$498,$A9,Cleaned_Data!$J$2:$J$498,B$5) -> 3693329 | C9: =SUMIFS(Cleaned_Data!$K$2:$K$498,Cleaned_Data!$Q$2:$Q$498,$A9,Cleaned_Data!$J$2:$J$498,C$5) -> 1442.48 | D9: =SUMIFS(Cleaned_Data!$K$2:$K$498,Cleaned_Data!$Q$2:$Q$498,$A9,Cleaned_Data!$J$2:$J$498,D$5) -> 0 | E9: =COUNTIFS(Cleaned_Data!$Q$2:$Q$498,$A9) -> 37
A10: 91-180 | B10: =SUMIFS(Cleaned_Data!$K$2:$K$498,Cleaned_Data!$Q$2:$Q$498,$A10,Cleaned_Data!$J$2:$J$498,B$5) -> 7143316.7 | C10: =SUMIFS(Cleaned_Data!$K$2:$K$498,Cleaned_Data!$Q$2:$Q$498,$A10,Cleaned_Data!$J$2:$J$498,C$5) -> 14300.94 | D10: =SUMIFS(Cleaned_Data!$K$2:$K$498,Cleaned_Data!$Q$2:$Q$498,$A10,Cleaned_Data!$J$2:$J$498,D$5) -> 23856.14 | E10: =COUNTIFS(Cleaned_Data!$Q$2:$Q$498,$A10) -> 89
A11: 180+ | B11: =SUMIFS(Cleaned_Data!$K$2:$K$498,Cleaned_Data!$Q$2:$Q$498,$A11,Cleaned_Data!$J$2:$J$498,B$5) -> 5245953.7 | C11: =SUMIFS(Cleaned_Data!$K$2:$K$498,Cleaned_Data!$Q$2:$Q$498,$A11,Cleaned_Data!$J$2:$J$498,C$5) -> -2335.7 | D11: =SUMIFS(Cleaned_Data!$K$2:$K$498,Cleaned_Data!$Q$2:$Q$498,$A11,Cleaned_Data!$J$2:$J$498,D$5) -> 0 | E11: =COUNTIFS(Cleaned_Data!$Q$2:$Q$498,$A11) -> 61
A12: Total | B12: =SUM(B6:B11) -> 45062632 | C12: =SUM(C6:C11) -> 77562.59 | D12: =SUM(D6:D11) -> 29887.14 | E12: =SUM(E6:E11) -> 497
A13: Report grand total (raw file footer) | B13: 45062632 | C13: 77562.59 | D13: 29887.14 | F13: Hard-coded from the "*** GRAND TOTAL ***" lines at the bottom of Raw_Data.
A14: Difference (should be 0) | B14: =ROUND(B12-B13,2) -> 0 | C14: =ROUND(C12-C13,2) -> 0 | D14: =ROUND(D12-D13,2) -> 0
A17: INR ageing by customer
A18: CustCode | B18: Customer | C18: Not due | D18: 1-30 | E18: 31-60 | F18: 61-90 | G18: 91-180 | H18: 180+ | I18: Total
A19: C10008 | B19: Sagar Polypack | C19: =SUMIFS(Cleaned_Data!$K$2:$K$498,Cleaned_Data!$A$2:$A$498,$A19,Cleaned_Data!$J$2:$J$498,"INR",Cleaned_Data!$Q$2:$Q$498,C$18) -> 793093.71 | D19: =SUMIFS(Cleaned_Data!$K$2:$K$498,Cleaned_Data!$A$2:$A$498,$A19,Cleaned_Data!$J$2:$J$498,"INR",Cleaned_Data!$Q$2:$Q$498,D$18) -> 271651.85 | E19: =SUMIFS(Cleaned_Data!$K$2:$K$498,Cleaned_Data!$A$2:$A$498,$A19,Cleaned_Data!$J$2:$J$498,"INR",Cleaned_Data!$Q$2:$Q$498,E$18) -> 242009.47 | F19: =SUMIFS(Cleaned_Data!$K$2:$K$498,Cleaned_Data!$A$2:$A$498,$A19,Cleaned_Data!$J$2:$J$498,"INR",Cleaned_Data!$Q$2:$Q$498,F$18) -> 104685 | G19: =SUMIFS(Cleaned_Data!$K$2:$K$498,Cleaned_Data!$A$2:$A$498,$A19,Cleaned_Data!$J$2:$J$498,"INR",Cleaned_Data!$Q$2:$Q$498,G$18) -> 39270 | H19: =SUMIFS(Cleaned_Data!$K$2:$K$498,Cleaned_Data!$A$2:$A$498,$A19,Cleaned_Data!$J$2:$J$498,"INR",Cleaned_Data!$Q$2:$Q$498,H$18) -> 123013.66 | I19: =SUM(C19:H19) -> 1573723.7
A20: C10011 | B20: Sri Lakshmi Traders | C20: =SUMIFS(Cleaned_Data!$K$2:$K$498,Cleaned_Data!$A$2:$A$498,$A20,Cleaned_Data!$J$2:$J$498,"INR",Cleaned_Data!$Q$2:$Q$498,C$18) -> 0 | D20: =SUMIFS(Cleaned_Data!$K$2:$K$498,Cleaned_Data!$A$2:$A$498,$A20,Cleaned_Data!$J$2:$J$498,"INR",Cleaned_Data!$Q$2:$Q$498,D$18) -> 140774 | E20: =SUMIFS(Cleaned_Data!$K$2:$K$498,Cleaned_Data!$A$2:$A$498,$A20,Cleaned_Data!$J$2:$J$498,"INR",Cleaned_Data!$Q$2:$Q$498,E$18) -> -20619.99 | F20: =SUMIFS(Cleaned_Data!$K$2:$K$498,Cleaned_Data!$A$2:$A$498,$A20,Cleaned_Data!$J$2:$J$498,"INR",Cleaned_Data!$Q$2:$Q$498,F$18) -> 0 | G20: =SUMIFS(Cleaned_Data!$K$2:$K$498,Cleaned_Data!$A$2:$A$498,$A20,Cleaned_Data!$J$2:$J$498,"INR",Cleaned_Data!$Q$2:$Q$498,G$18) -> 0 | H20: =SUMIFS(Cleaned_Data!$K$2:$K$498,Cleaned_Data!$A$2:$A$498,$A20,Cleaned_Data!$J$2:$J$498,"INR",Cleaned_Data!$Q$2:$Q$498,H$18) -> 0 | I20: =SUM(C20:H20) -> 120154.01
A21: C10017 | B21: Jayanagar Hardware Mart | C21: =SUMIFS(Cleaned_Data!$K$2:$K$498,Cleaned_Data!$A$2:$A$498,$A21,Cleaned_Data!$J$2:$J$498,"INR",Cleaned_Data!$Q$2:$Q$498,C$18) -> 0 | D21: =SUMIFS(Cleaned_Data!$K$2:$K$498,Cleaned_Data!$A$2:$A$498,$A21,Cleaned_Data!$J$2:$J$498,"INR",Cleaned_Data!$Q$2:$Q$498,D$18) -> 43424 | E21: =SUMIFS(Cleaned_Data!$K$2:$K$498,Cleaned_Data!$A$2:$A$498,$A21,Cleaned_Data!$J$2:$J$498,"INR",Cleaned_Data!$Q$2:$Q$498,E$18) -> 0 | F21: =SUMIFS(Cleaned_Data!$K$2:$K$498,Cleaned_Data!$A$2:$A$498,$A21,Cleaned_Data!$J$2:$J$498,"INR",Cleaned_Data!$Q$2:$Q$498,F$18) -> 61360 | G21: =SUMIFS(Cleaned_Data!$K$2:$K$498,Cleaned_Data!$A$2:$A$498,$A21,Cleaned_Data!$J$2:$J$498,"INR",Cleaned_Data!$Q$2:$Q$498,G$18) -> 0 | H21: =SUMIFS(Cleaned_Data!$K$2:$K$498,Cleaned_Data!$A$2:$A$498,$A21,Cleaned_Data!$J$2:$J$498,"INR",Cleaned_Data!$Q$2:$Q$498,H$18) -> 0 | I21: =SUM(C21:H21) -> 104784
A22: C10021 | B22: Konkan Marine Equipments | C22: =SUMIFS(Cleaned_Data!$K$2:$K$498,Cleaned_Data!$A$2:$A$498,$A22,Cleaned_Data!$J$2:$J$498,"INR",Cleaned_Data!$Q$2:$Q$498,C$18) -> 817654.53 | D22: =SUMIFS(Cleaned_Data!$K$2:$K$498,Cleaned_Data!$A$2:$A$498,$A22,Cleaned_Data!$J$2:$J$498,"INR",Cleaned_Data!$Q$2:$Q$498,D$18) -> 114040.89 | E22: =SUMIFS(Cleaned_Data!$K$2:$K$498,Cleaned_Data!$A$2:$A$498,$A22,Cleaned_Data!$J$2:$J$498,"INR",Cleaned_Data!$Q$2:$Q$498,E$18) -> 346721.57 | F22: =SUMIFS(Cleaned_Data!$K$2:$K$498,Cleaned_Data!$A$2:$A$498,$A22,Cleaned_Data!$J$2:$J$498,"INR",Cleaned_Data!$Q$2:$Q$498,F$18) -> 611380 | G22: =SUMIFS(Cleaned_Data!$K$2:$K$498,Cleaned_Data!$A$2:$A$498,$A22,Cleaned_Data!$J$2:$J$498,"INR",Cleaned_Data!$Q$2:$Q$498,G$18) -> 53018 | H22: =SUMIFS(Cleaned_Data!$K$2:$K$498,Cleaned_Data!$A$2:$A$498,$A22,Cleaned_Data!$J$2:$J$498,"INR",Cleaned_Data!$Q$2:$Q$498,H$18) -> 617161 | I22: =SUM(C22:H22) -> 2559976
A23: C10029 | B23: Peenya Precision Tools | C23: =SUMIFS(Cleaned_Data!$K$2:$K$498,Cleaned_Data!$A$2:$A$498,$A23,Cleaned_Data!$J$2:$J$498,"INR",Cleaned_Data!$Q$2:$Q$498,C$18) -> 617186.9 | D23: =SUMIFS(Cleaned_Data!$K$2:$K$498,Cleaned_Data!$A$2:$A$498,$A23,Cleaned_Data!$J$2:$J$498,"INR",Cleaned_Data!$Q$2:$Q$498,D$18) -> 0 | E23: =SUMIFS(Cleaned_Data!$K$2:$K$498,Cleaned_Data!$A$2:$A$498,$A23,Cleaned_Data!$J$2:$J$498,"INR",Cleaned_Data!$Q$2:$Q$498,E$18) -> 52392 | F23: =SUMIFS(Cleaned_Data!$K$2:$K$498,Cleaned_Data!$A$2:$A$498,$A23,Cleaned_Data!$J$2:$J$498,"INR",Cleaned_Data!$Q$2:$Q$498,F$18) -> 118944 | G23: =SUMIFS(Cleaned_Data!$K$2:$K$498,Cleaned_Data!$A$2:$A$498,$A23,Cleaned_Data!$J$2:$J$498,"INR",Cleaned_Data!$Q$2:$Q$498,G$18) -> 0 | H23: =SUMIFS(Cleaned_Data!$K$2:$K$498,Cleaned_Data!$A$2:$A$498,$A23,Cleaned_Data!$J$2:$J$498,"INR",Cleaned_Data!$Q$2:$Q$498,H$18) -> 0 | I23: =SUM(C23:H23) -> 788522.9
A24: C10031 | B24: Hosakote Industrial Estate Traders | C24: =SUMIFS(Cleaned_Data!$K$2:$K$498,Cleaned_Data!$A$2:$A$498,$A24,Cleaned_Data!$J$2:$J$498,"INR",Cleaned_Data!$Q$2:$Q$498,C$18) -> 312503.87 | D24: =SUMIFS(Cleaned_Data!$K$2:$K$498,Cleaned_Data!$A$2:$A$498,$A24,Cleaned_Data!$J$2:$J$498,"INR",Cleaned_Data!$Q$2:$Q$498,D$18) -> 0 | E24: =SUMIFS(Cleaned_Data!$K$2:$K$498,Cleaned_Data!$A$2:$A$498,$A24,Cleaned_Data!$J$2:$J$498,"INR",Cleaned_Data!$Q$2:$Q$498,E$18) -> 12238.72 | F24: =SUMIFS(Cleaned_Data!$K$2:$K$498,Cleaned_Data!$A$2:$A$498,$A24,Cleaned_Data!$J$2:$J$498,"INR",Cleaned_Data!$Q$2:$Q$498,F$18) -> -15900 | G24: =SUMIFS(Cleaned_Data!$K$2:$K$498,Cleaned_Data!$A$2:$A$498,$A24,Cleaned_Data!$J$2:$J$498,"INR",Cleaned_Data!$Q$2:$Q$498,G$18) -> -363102 | H24: =SUMIFS(Cleaned_Data!$K$2:$K$498,Cleaned_Data!$A$2:$A$498,$A24,Cleaned_Data!$J$2:$J$498,"INR",Cleaned_Data!$Q$2:$Q$498,H$18) -> 94282 | I24: =SUM(C24:H24) -> 40022.59
A25: C10037 | B25: Malnad Agro Foods Pvt Ltd | C25: =SUMIFS(Cleaned_Data!$K$2:$K$498,Cleaned_Data!$A$2:$A$498,$A25,Cleaned_Data!$J$2:$J$498,"INR",Cleaned_Data!$Q$2:$Q$498,C$18) -> 457342 | D25: =SUMIFS(Cleaned_Data!$K$2:$K$498,Cleaned_Data!$A$2:$A$498,$A25,Cleaned_Data!$J$2:$J$498,"INR",Cleaned_Data!$Q$2:$Q$498,D$18) -> -239066 | E25: =SUMIFS(Cleaned_Data!$K$2:$K$498,Cleaned_Data!$A$2:$A$498,$A25,Cleaned_Data!$J$2:$J$498,"INR",Cleaned_Data!$Q$2:$Q$498,E$18) -> 140774 | F25: =SUMIFS(Cleaned_Data!$K$2:$K$498,Cleaned_Data!$A$2:$A$498,$A25,Cleaned_Data!$J$2:$J$498,"INR",Cleaned_Data!$Q$2:$Q$498,F$18) -> 2950 | G25: =SUMIFS(Cleaned_Data!$K$2:$K$498,Cleaned_Data!$A$2:$A$498,$A25,Cleaned_Data!$J$2:$J$498,"INR",Cleaned_Data!$Q$2:$Q$498,G$18) -> 79255.41 | H25: =SUMIFS(Cleaned_Data!$K$2:$K$498,Cleaned_Data!$A$2:$A$498,$A25,Cleaned_Data!$J$2:$J$498,"INR",Cleaned_Data!$Q$2:$Q$498,H$18) -> 0 | I25: =SUM(C25:H25) -> 441255.41
A26: C10050 | B26: Deccan Pumps & Motors Pvt Ltd | C26: =SUMIFS(Cleaned_Data!$K$2:$K$498,Cleaned_Data!$A$2:$A$498,$A26,Cleaned_Data!$J$2:$J$498,"INR",Cleaned_Data!$Q$2:$Q$498,C$18) -> 220683.66 | D26: =SUMIFS(Cleaned_Data!$K$2:$K$498,Cleaned_Data!$A$2:$A$498,$A26,Cleaned_Data!$J$2:$J$498,"INR",Cleaned_Data!$Q$2:$Q$498,D$18) -> 0 | E26: =SUMIFS(Cleaned_Data!$K$2:$K$498,Cleaned_Data!$A$2:$A$498,$A26,Cleaned_Data!$J$2:$J$498,"INR",Cleaned_Data!$Q$2:$Q$498,E$18) -> 183179.57 | F26: =SUMIFS(Cleaned_Data!$K$2:$K$498,Cleaned_Data!$A$2:$A$498,$A26,Cleaned_Data!$J$2:$J$498,"INR",Cleaned_Data!$Q$2:$Q$498,F$18) -> 0 | G26: =SUMIFS(Cleaned_Data!$K$2:$K$498,Cleaned_Data!$A$2:$A$498,$A26,Cleaned_Data!$J$2:$J$498,"INR",Cleaned_Data!$Q$2:$Q$498,G$18) -> 963507.32 | H26: =SUMIFS(Cleaned_Data!$K$2:$K$498,Cleaned_Data!$A$2:$A$498,$A26,Cleaned_Data!$J$2:$J$498,"INR",Cleaned_Data!$Q$2:$Q$498,H$18) -> 282481.8 | I26: =SUM(C26:H26) -> 1649852.4
A27: C10060 | B27: Bhagyalakshmi Enterprises | C27: =SUMIFS(Cleaned_Data!$K$2:$K$498,Cleaned_Data!$A$2:$A$498,$A27,Cleaned_Data!$J$2:$J$498,"INR",Cleaned_Data!$Q$2:$Q$498,C$18) -> 0 | D27: =SUMIFS(Cleaned_Data!$K$2:$K$498,Cleaned_Data!$A$2:$A$498,$A27,Cleaned_Data!$J$2:$J$498,"INR",Cleaned_Data!$Q$2:$Q$498,D$18) -> 37237.34 | E27: =SUMIFS(Cleaned_Data!$K$2:$K$498,Cleaned_Data!$A$2:$A$498,$A27,Cleaned_Data!$J$2:$J$498,"INR",Cleaned_Data!$Q$2:$Q$498,E$18) -> 50740 | F27: =SUMIFS(Cleaned_Data!$K$2:$K$498,Cleaned_Data!$A$2:$A$498,$A27,Cleaned_Data!$J$2:$J$498,"INR",Cleaned_Data!$Q$2:$Q$498,F$18) -> 0 | G27: =SUMIFS(Cleaned_Data!$K$2:$K$498,Cleaned_Data!$A$2:$A$498,$A27,Cleaned_Data!$J$2:$J$498,"INR",Cleaned_Data!$Q$2:$Q$498,G$18) -> 236760.76 | H27: =SUMIFS(Cleaned_Data!$K$2:$K$498,Cleaned_Data!$A$2:$A$498,$A27,Cleaned_Data!$J$2:$J$498,"INR",Cleaned_Data!$Q$2:$Q$498,H$18) -> 0 | I27: =SUM(C27:H27) -> 324738.1
A28: C10071 | B28: Godavari Fertiliser Dealers | C28: =SUMIFS(Cleaned_Data!$K$2:$K$498,Cleaned_Data!$A$2:$A$498,$A28,Cleaned_Data!$J$2:$J$498,"INR",Cleaned_Data!$Q$2:$Q$498,C$18) -> 544722.23 | D28: =SUMIFS(Cleaned_Data!$K$2:$K$498,Cleaned_Data!$A$2:$A$498,$A28,Cleaned_Data!$J$2:$J$498,"INR",Cleaned_Data!$Q$2:$Q$498,D$18) -> 0 | E28: =SUMIFS(Cleaned_Data!$K$2:$K$498,Cleaned_Data!$A$2:$A$498,$A28,Cleaned_Data!$J$2:$J$498,"INR",Cleaned_Data!$Q$2:$Q$498,E$18) -> 0 | F28: =SUMIFS(Cleaned_Data!$K$2:$K$498,Cleaned_Data!$A$2:$A$498,$A28,Cleaned_Data!$J$2:$J$498,"INR",Cleaned_Data!$Q$2:$Q$498,F$18) -> 281314.07 | G28: =SUMIFS(Cleaned_Data!$K$2:$K$498,Cleaned_Data!$A$2:$A$498,$A28,Cleaned_Data!$J$2:$J$498,"INR",Cleaned_Data!$Q$2:$Q$498,G$18) -> 187040.84 | H28: =SUMIFS(Cleaned_Data!$K$2:$K$498,Cleaned_Data!$A$2:$A$498,$A28,Cleaned_Data!$J$2:$J$498,"INR",Cleaned_Data!$Q$2:$Q$498,H$18) -> 164110.95 | I28: =SUM(C28:H28) -> 1177188.1
A29: C10074 | B29: Tejas Precision Castings | C29: =SUMIFS(Cleaned_Data!$K$2:$K$498,Cleaned_Data!$A$2:$A$498,$A29,Cleaned_Data!$J$2:$J$498,"INR",Cleaned_Data!$Q$2:$Q$498,C$18) -> 617427.11 | D29: =SUMIFS(Cleaned_Data!$K$2:$K$498,Cleaned_Data!$A$2:$A$498,$A29,Cleaned_Data!$J$2:$J$498,"INR",Cleaned_Data!$Q$2:$Q$498,D$18) -> 0 | E29: =SUMIFS(Cleaned_Data!$K$2:$K$498,Cleaned_Data!$A$2:$A$498,$A29,Cleaned_Data!$J$2:$J$498,"INR",Cleaned_Data!$Q$2:$Q$498,E$18) -> 0 | F29: =SUMIFS(Cleaned_Data!$K$2:$K$498,Cleaned_Data!$A$2:$A$498,$A29,Cleaned_Data!$J$2:$J$498,"INR",Cleaned_Data!$Q$2:$Q$498,F$18) -> 0 | G29: =SUMIFS(Cleaned_Data!$K$2:$K$498,Cleaned_Data!$A$2:$A$498,$A29,Cleaned_Data!$J$2:$J$498,"INR",Cleaned_Data!$Q$2:$Q$498,G$18) -> -79000 | H29: =SUMIFS(Cleaned_Data!$K$2:$K$498,Cleaned_Data!$A$2:$A$498,$A29,Cleaned_Data!$J$2:$J$498,"INR",Cleaned_Data!$Q$2:$Q$498,H$18) -> 130527.14 | I29: =SUM(C29:H29) -> 668954.25
A30: C10081 | B30: Maruthi Tools & Dies | C30: =SUMIFS(Cleaned_Data!$K$2:$K$498,Cleaned_Data!$A$2:$A$498,$A30,Cleaned_Data!$J$2:$J$498,"INR",Cleaned_Data!$Q$2:$Q$498,C$18) -> 0 | D30: =SUMIFS(Cleaned_Data!$K$2:$K$498,Cleaned_Data!$A$2:$A$498,$A30,Cleaned_Data!$J$2:$J$498,"INR",Cleaned_Data!$Q$2:$Q$498,D$18) -> 56050 | E30: =SUMIFS(Cleaned_Data!$K$2:$K$498,Cleaned_Data!$A$2:$A$498,$A30,Cleaned_Data!$J$2:$J$498,"INR",Cleaned_Data!$Q$2:$Q$498,E$18) -> 0 | F30: =SUMIFS(Cleaned_Data!$K$2:$K$498,Cleaned_Data!$A$2:$A$498,$A30,Cleaned_Data!$J$2:$J$498,"INR",Cleaned_Data!$Q$2:$Q$498,F$18) -> 0 | G30: =SUMIFS(Cleaned_Data!$K$2:$K$498,Cleaned_Data!$A$2:$A$498,$A30,Cleaned_Data!$J$2:$J$498,"INR",Cleaned_Data!$Q$2:$Q$498,G$18) -> 94147.19 | H30: =SUMIFS(Cleaned_Data!$K$2:$K$498,Cleaned_Data!$A$2:$A$498,$A30,Cleaned_Data!$J$2:$J$498,"INR",Cleaned_Data!$Q$2:$Q$498,H$18) -> 0 | I30: =SUM(C30:H30) -> 150197.19
... A73: C10371 | B73: Vijayanagar Building Supplies | C73: =SUMIFS(Cleaned_Data!$K$2:$K$498,Cleaned_Data!$A$2:$A$498,$A73,Cleaned_Data!$J$2:$J$498,"INR",Cleaned_Data!$Q$2:$Q$498,C$18) -> 84223 | D73: =SUMIFS(Cleaned_Data!$K$2:$K$498,Cleaned_Data!$A$2:$A$498,$A73,Cleaned_Data!$J$2:$J$498,"INR",Cleaned_Data!$Q$2:$Q$498,D$18) -> 16859.8 | E73: =SUMIFS(Cleaned_Data!$K$2:$K$498,Cleaned_Data!$A$2:$A$498,$A73,Cleaned_Data!$J$2:$J$498,"INR",Cleaned_Data!$Q$2:$Q$498,E$18) -> 0 | F73: =SUMIFS(Cleaned_Data!$K$2:$K$498,Cleaned_Data!$A$2:$A$498,$A73,Cleaned_Data!$J$2:$J$498,"INR",Cleaned_Data!$Q$2:$Q$498,F$18) -> 0 | G73: =SUMIFS(Cleaned_Data!$K$2:$K$498,Cleaned_Data!$A$2:$A$498,$A73,Cleaned_Data!$J$2:$J$498,"INR",Cleaned_Data!$Q$2:$Q$498,G$18) -> 0 | H73: =SUMIFS(Cleaned_Data!$K$2:$K$498,Cleaned_Data!$A$2:$A$498,$A73,Cleaned_Data!$J$2:$J$498,"INR",Cleaned_Data!$Q$2:$Q$498,H$18) -> 0 | I73: =SUM(C73:H73) -> 101082.8
A74: Total | C74: =SUM(C19:C73) -> 17475656 | D74: =SUM(D19:D73) -> 6971835.1 | E74: =SUM(E19:E73) -> 4532542.1 | F74: =SUM(F19:F73) -> 3693329 | G74: =SUM(G19:G73) -> 7143316.7 | H74: =SUM(H19:H73) -> 5245953.7 | I74: =SUM(I19:I73) -> 45062632

Sheet Cust_Master
A1: CustCode | B1: CustomerName | C1: Region | D1: Segment | E1: DefaultTermsDays
A2: C10008 | B2: Sagar Polypack | C2: Andhra Pradesh | D2: Packaging | E2: 30
A3: C10011 | B3: Sri Lakshmi Traders | C3: Tamil Nadu | D3: Trading | E3: 30
A4: C10017 | B4: Jayanagar Hardware Mart | C4: Bengaluru | D4: Trading | E4: 15
A5: C10021 | B5: Konkan Marine Equipments | C5: Maharashtra | D5: Engineering | E5: 45
A6: C10029 | B6: Peenya Precision Tools | C6: Bengaluru | D6: Engineering | E6: 45
A7: C10031 | B7: Hosakote Industrial Estate Traders | C7: Karnataka | D7: Trading | E7: 30
A8: C10037 | B8: Malnad Agro Foods Pvt Ltd | C8: Karnataka | D8: Agri | E8: 30
A9: C10048 | B9: Brightway Components GmbH | C9: Export | D9: Automotive | E9: 60
A10: C10050 | B10: Deccan Pumps & Motors Pvt Ltd | C10: Telangana | D10: Engineering | E10: 60
A11: C10060 | B11: Bhagyalakshmi Enterprises | C11: Karnataka | D11: Trading | E11: 30
A12: C10071 | B12: Godavari Fertiliser Dealers | C12: Andhra Pradesh | D12: Agri | E12: 45
A13: C10074 | B13: Tejas Precision Castings | C13: Bengaluru | D13: Automotive | E13: 45
... A58: C10371 | B58: Vijayanagar Building Supplies | C58: Karnataka | D58: Construction | E58: 30

Sheet Rep_Alias
A1: Alias | B1: SalesRep | D1: Alias = the rep name as typed, reduced to lower-case letters (Ramesh K. -> rameshk).
A2: anithar | B2: Anitha Rao
A3: anitharao | B3: Anitha Rao
A4: arao | B4: Anitha Rao
A5: divya | B5: Divya Nair
A6: divyan | B6: Divya Nair
A7: divyanair | B7: Divya Nair
A8: dnair | B8: Divya Nair
A9: imran | B9: Imran Sheikh
A10: imrans | B10: Imran Sheikh
A11: imransheikh | B11: Imran Sheikh
A12: isheikh | B12: Imran Sheikh
A13: phegde | B13: Prakash Hegde
... A24: sureshbabu | B24: Suresh Babu

Sheet M_Code
A1: // AR_Open_Items_Clean
A2: // Raw ERP open-items print (CSV) -> one tidy row per open document.
A3: // Needs: pRepoPath, pAsOfDate, fnCleanText, fnParseDate, fnParseAmount, fnTermsDays, dimCustomer, dimRepAlias
A4: let
A5: // ---- lookups kept at the top so they are easy to extend --------------------------------
A6: DocTypeMap = [
A7: INV = "Invoice", INVOICE = "Invoice",
A8: CN = "Credit Note", #"CR NOTE" = "Credit Note", #"CREDIT NOTE" = "Credit Note",
A9: DN = "Debit Note", #"DR NOTE" = "Debit Note",
A10: PMT = "On-Account Receipt", RCT = "On-Account Receipt", ADV = "On-Account Receipt",
A11: JV = "Journal"
A12: ],
... A207: Sorted
